2018-10-15 15:57:35-ERROR [base.py:process_exception():5]: LOGIN_FAILED
Traceback (most recent call last):
  File "/Users/thangdinh/Projects/VMS/src/server/api/v1/users.py", line 16, in login
    request_json.get('password'))
  File "/Users/thangdinh/Projects/VMS/src/server/bus/user_manager.py", line 22, in login
    raise UserException(ErrorCode.LOGIN_FAILED)
utils.user_exception.UserException: LOGIN_FAILED
2018-10-15 15:57:53-ERROR [base.py:process_exception():5]: 'Camera' object has no attribute 'human_tracking_regions'
Traceback (most recent call last):
  File "/Users/thangdinh/Projects/VMS/src/server/api/v1/cameras.py", line 93, in search
    request_json.get('page_size'))
  File "/Users/thangdinh/Projects/VMS/src/server/bus/camera_manager.py", line 202, in search_cameras
    return JsonResult(True, Utils.json_collection(cameras)).json_paginate(cameras)
  File "/Users/thangdinh/Projects/VMS/src/server/utils/utils.py", line 39, in json_collection
    json.append(obj.json())
  File "/Users/thangdinh/Projects/VMS/src/server/models/camera.py", line 83, in json
    if not Utils.is_null_or_empty(self.human_tracking_regions):
  File "/Library/Frameworks/Python.framework/Versions/3.6/lib/python3.6/site-packages/orator/orm/model.py", line 2838, in __getattr__
    return self.get_attribute(item)
  File "/Library/Frameworks/Python.framework/Versions/3.6/lib/python3.6/site-packages/orator/orm/model.py", line 2301, in get_attribute
    relation = original or super(Model, self).__getattribute__(key)
AttributeError: 'Camera' object has no attribute 'human_tracking_regions'
